Workbook

Sheet Контрагенты
B2: Расходы по контрагентам, счёт 60
B3: Данные из файла бухгалтерии. Меняете статью или блок — суммы на листах «Статьи» и «Свод» пересчитываются сами.
G4: № в выборке →
B5: Контрагент | C5: Оплачено | D5: Статья | E5: Блок | G5: 0
B6: Маркарян Максим Рачьянович ИП | C6: 10966274 | D6: Гонорары ИП хирургов | E6: медицинские | G6: =IF(OR($D6=Свод!$C$5,$E6=Свод!$C$5),MAX($G$5:$G5)+1,"")
B7: БУРДИНА Е.С. ИП | C7: 5382764 | D7: Гонорары ИП хирургов | E7: медицинские | G7: =IF(OR($D7=Свод!$C$5,$E7=Свод!$C$5),MAX($G$5:$G6)+1,"")
B8: Сехина Виктория Дмитриевна | C8: 4692500 | D8: Урегулирование досудебного спора | E8: управленческие | G8: =IF(OR($D8=Свод!$C$5,$E8=Свод!$C$5),MAX($G$5:$G7)+1,"")
B9: Ужахов Тимур Магомедович ИП | C9: 4518074 | D9: Гонорары ИП хирургов | E9: медицинские | G9: =IF(OR($D9=Свод!$C$5,$E9=Свод!$C$5),MAX($G$5:$G8)+1,"")
B10: КЛОВЕРМЕД ООО | C10: 4196900 | D10: Импланты | E10: медицинские | G10: =IF(OR($D10=Свод!$C$5,$E10=Свод!$C$5),MAX($G$5:$G9)+1,"")
B11: Завиркин Антон Владимирович ИП | C11: 2887658 | D11: ИП Завиркин А.В. | E11: медицинские | G11: =IF(OR($D11=Свод!$C$5,$E11=Свод!$C$5),MAX($G$5:$G10)+1,"")
B12: Маржохов Астемир Ануарович ИП | C12: 2811745 | D12: Гонорары ИП хирургов | E12: медицинские | G12: =IF(OR($D12=Свод!$C$5,$E12=Свод!$C$5),MAX($G$5:$G11)+1,"")
B13: Габеев Алан Ирбекович ИП | C13: 2631347 | D13: Гонорары ИП хирургов | E13: медицинские | G13: =IF(OR($D13=Свод!$C$5,$E13=Свод!$C$5),MAX($G$5:$G12)+1,"")
B14: Ласукова Екатерина Борисовна | C14: 2505800 | D14: Маркетинговые услуги | E14: управленческие | G14: =IF(OR($D14=Свод!$C$5,$E14=Свод!$C$5),MAX($G$5:$G13)+1,"")
B15: Пономарёва Елена Юрьевна ИП | C15: 2272677 | D15: Гонорары ИП хирургов | E15: медицинские | G15: =IF(OR($D15=Свод!$C$5,$E15=Свод!$C$5),MAX($G$5:$G14)+1,"")
B16: БУРДИН С. А. ИП | C16: 2227217 | D16: Гонорары ИП хирургов | E16: медицинские | G16: =IF(OR($D16=Свод!$C$5,$E16=Свод!$C$5),MAX($G$5:$G15)+1,"")
B17: Ханукаев Александр Ильич | C17: 2210015 | D17: Гонорары ИП хирургов | E17: медицинские | G17: =IF(OR($D17=Свод!$C$5,$E17=Свод!$C$5),MAX($G$5:$G16)+1,"")
... B124: Cамозанятый Котлярова Олеся Владимировна | C124: 1100 | D124: Консультационные услуги | E124: управленческие | G124: =IF(OR($D124=Свод!$C$5,$E124=Свод!$C$5),MAX($G$5:$G123)+1,"")
B125: Сумма по контрагентам | C125: =SUM(C6:C124)
B126: Корректировка 1 | C126: -169644.37 | D126: ручная поправка бухгалтерии
B127: Корректировка 2 | C127: -6000 | D127: ручная поправка бухгалтерии
B128: Корректировка 3 | C128: -44711 | D128: ручная поправка бухгалтерии
B129: ИТОГО ПО СЧЁТУ 60 | C129: =C125+SUM(C126:C128)
B131: Ремонт Самокатная 1 стр.12 | C131: 11000000 | D131: За счет кредитной линии | E131: в расходы учредителей не входит

Sheet Списки
A1: медицинские
A2: управленческие
A3: IT услуги
A4: Анализы
A5: Аренда Inmode
A6: Аренда Самокатная 1 стр1
A7: Аренда кофемашины
A8: Белье
A9: Битрикс 24
A10: Бланки, мед.журналы, мед.книжки
A11: Внедрение финансового учёта
A12: Вода
... A73: Электрооборудование

Sheet Свод
B2: Свод и выборка
B3: Выберите блок или статью в списке — ниже развернётся состав.
B5: Блок или статья: | C5: медицинские
B6: Сумма: | C6: =SUMIF(Контрагенты!$E$6:$E$124,$C$5,Контрагенты!$C$6:$C$124)+SUMIF(Контрагенты!$D$6:$D$124,$C$5,Контрагенты!$C$6:$C$124) | D6: Контрагентов: | E6: =COUNTIF(Контрагенты!$E$6:$E$124,$C$5)+COUNTIF(Контрагенты!$D$6:$D$124,$C$5)
B8: Контрагент | C8: Оплачено | D8: Статья | E8: Блок
B9: =IFERROR(INDEX(Контрагенты!$B$6:$B$124,MATCH(1,Контрагенты!$G$6:$G$124,0)),"") | C9: =IFERROR(INDEX(Контрагенты!$C$6:$C$124,MATCH(1,Контрагенты!$G$6:$G$124,0)),"") | D9: =IFERROR(INDEX(Контрагенты!$D$6:$D$124,MATCH(1,Контрагенты!$G$6:$G$124,0)),"") | E9: =IFERROR(INDEX(Контрагенты!$E$6:$E$124,MATCH(1,Контрагенты!$G$6:$G$124,0)),"")
B10: =IFERROR(INDEX(Контрагенты!$B$6:$B$124,MATCH(2,Контрагенты!$G$6:$G$124,0)),"") | C10: =IFERROR(INDEX(Контрагенты!$C$6:$C$124,MATCH(2,Контрагенты!$G$6:$G$124,0)),"") | D10: =IFERROR(INDEX(Контрагенты!$D$6:$D$124,MATCH(2,Контрагенты!$G$6:$G$124,0)),"") | E10: =IFERROR(INDEX(Контрагенты!$E$6:$E$124,MATCH(2,Контрагенты!$G$6:$G$124,0)),"")
B11: =IFERROR(INDEX(Контрагенты!$B$6:$B$124,MATCH(3,Контрагенты!$G$6:$G$124,0)),"") | C11: =IFERROR(INDEX(Контрагенты!$C$6:$C$124,MATCH(3,Контрагенты!$G$6:$G$124,0)),"") | D11: =IFERROR(INDEX(Контрагенты!$D$6:$D$124,MATCH(3,Контрагенты!$G$6:$G$124,0)),"") | E11: =IFERROR(INDEX(Контрагенты!$E$6:$E$124,MATCH(3,Контрагенты!$G$6:$G$124,0)),"")
B12: =IFERROR(INDEX(Контрагенты!$B$6:$B$124,MATCH(4,Контрагенты!$G$6:$G$124,0)),"") | C12: =IFERROR(INDEX(Контрагенты!$C$6:$C$124,MATCH(4,Контрагенты!$G$6:$G$124,0)),"") | D12: =IFERROR(INDEX(Контрагенты!$D$6:$D$124,MATCH(4,Контрагенты!$G$6:$G$124,0)),"") | E12: =IFERROR(INDEX(Контрагенты!$E$6:$E$124,MATCH(4,Контрагенты!$G$6:$G$124,0)),"")
B13: =IFERROR(INDEX(Контрагенты!$B$6:$B$124,MATCH(5,Контрагенты!$G$6:$G$124,0)),"") | C13: =IFERROR(INDEX(Контрагенты!$C$6:$C$124,MATCH(5,Контрагенты!$G$6:$G$124,0)),"") | D13: =IFERROR(INDEX(Контрагенты!$D$6:$D$124,MATCH(5,Контрагенты!$G$6:$G$124,0)),"") | E13: =IFERROR(INDEX(Контрагенты!$E$6:$E$124,MATCH(5,Контрагенты!$G$6:$G$124,0)),"")
B14: =IFERROR(INDEX(Контрагенты!$B$6:$B$124,MATCH(6,Контрагенты!$G$6:$G$124,0)),"") | C14: =IFERROR(INDEX(Контрагенты!$C$6:$C$124,MATCH(6,Контрагенты!$G$6:$G$124,0)),"") | D14: =IFERROR(INDEX(Контрагенты!$D$6:$D$124,MATCH(6,Контрагенты!$G$6:$G$124,0)),"") | E14: =IFERROR(INDEX(Контрагенты!$E$6:$E$124,MATCH(6,Контрагенты!$G$6:$G$124,0)),"")
B15: =IFERROR(INDEX(Контрагенты!$B$6:$B$124,MATCH(7,Контрагенты!$G$6:$G$124,0)),"") | C15: =IFERROR(INDEX(Контрагенты!$C$6:$C$124,MATCH(7,Контрагенты!$G$6:$G$124,0)),"") | D15: =IFERROR(INDEX(Контрагенты!$D$6:$D$124,MATCH(7,Контрагенты!$G$6:$G$124,0)),"") | E15: =IFERROR(INDEX(Контрагенты!$E$6:$E$124,MATCH(7,Контрагенты!$G$6:$G$124,0)),"")
B16: =IFERROR(INDEX(Контрагенты!$B$6:$B$124,MATCH(8,Контрагенты!$G$6:$G$124,0)),"") | C16: =IFERROR(INDEX(Контрагенты!$C$6:$C$124,MATCH(8,Контрагенты!$G$6:$G$124,0)),"") | D16: =IFERROR(INDEX(Контрагенты!$D$6:$D$124,MATCH(8,Контрагенты!$G$6:$G$124,0)),"") | E16: =IFERROR(INDEX(Контрагенты!$E$6:$E$124,MATCH(8,Контрагенты!$G$6:$G$124,0)),"")
B17: =IFERROR(INDEX(Контрагенты!$B$6:$B$124,MATCH(9,Контрагенты!$G$6:$G$124,0)),"") | C17: =IFERROR(INDEX(Контрагенты!$C$6:$C$124,MATCH(9,Контрагенты!$G$6:$G$124,0)),"") | D17: =IFERROR(INDEX(Контрагенты!$D$6:$D$124,MATCH(9,Контрагенты!$G$6:$G$124,0)),"") | E17: =IFERROR(INDEX(Контрагенты!$E$6:$E$124,MATCH(9,Контрагенты!$G$6:$G$124,0)),"")
B18: =IFERROR(INDEX(Контрагенты!$B$6:$B$124,MATCH(10,Контрагенты!$G$6:$G$124,0)),"") | C18: =IFERROR(INDEX(Контрагенты!$C$6:$C$124,MATCH(10,Контрагенты!$G$6:$G$124,0)),"") | D18: =IFERROR(INDEX(Контрагенты!$D$6:$D$124,MATCH(10,Контрагенты!$G$6:$G$124,0)),"") | E18: =IFERROR(INDEX(Контрагенты!$E$6:$E$124,MATCH(10,Контрагенты!$G$6:$G$124,0)),"")
B19: =IFERROR(INDEX(Контрагенты!$B$6:$B$124,MATCH(11,Контрагенты!$G$6:$G$124,0)),"") | C19: =IFERROR(INDEX(Контрагенты!$C$6:$C$124,MATCH(11,Контрагенты!$G$6:$G$124,0)),"") | D19: =IFERROR(INDEX(Контрагенты!$D$6:$D$124,MATCH(11,Контрагенты!$G$6:$G$124,0)),"") | E19: =IFERROR(INDEX(Контрагенты!$E$6:$E$124,MATCH(11,Контрагенты!$G$6:$G$124,0)),"")
B20: =IFERROR(INDEX(Контрагенты!$B$6:$B$124,MATCH(12,Контрагенты!$G$6:$G$124,0)),"") | C20: =IFERROR(INDEX(Контрагенты!$C$6:$C$124,MATCH(12,Контрагенты!$G$6:$G$124,0)),"") | D20: =IFERROR(INDEX(Контрагенты!$D$6:$D$124,MATCH(12,Контрагенты!$G$6:$G$124,0)),"") | E20: =IFERROR(INDEX(Контрагенты!$E$6:$E$124,MATCH(12,Контрагенты!$G$6:$G$124,0)),"")
B21: =IFERROR(INDEX(Контрагенты!$B$6:$B$124,MATCH(13,Контрагенты!$G$6:$G$124,0)),"") | C21: =IFERROR(INDEX(Контрагенты!$C$6:$C$124,MATCH(13,Контрагенты!$G$6:$G$124,0)),"") | D21: =IFERROR(INDEX(Контрагенты!$D$6:$D$124,MATCH(13,Контрагенты!$G$6:$G$124,0)),"") | E21: =IFERROR(INDEX(Контрагенты!$E$6:$E$124,MATCH(13,Контрагенты!$G$6:$G$124,0)),"")
B22: =IFERROR(INDEX(Контрагенты!$B$6:$B$124,MATCH(14,Контрагенты!$G$6:$G$124,0)),"") | C22: =IFERROR(INDEX(Контрагенты!$C$6:$C$124,MATCH(14,Контрагенты!$G$6:$G$124,0)),"") | D22: =IFERROR(INDEX(Контрагенты!$D$6:$D$124,MATCH(14,Контрагенты!$G$6:$G$124,0)),"") | E22: =IFERROR(INDEX(Контрагенты!$E$6:$E$124,MATCH(14,Контрагенты!$G$6:$G$124,0)),"")
B23: =IFERROR(INDEX(Контрагенты!$B$6:$B$124,MATCH(15,Контрагенты!$G$6:$G$124,0)),"") | C23: =IFERROR(INDEX(Контрагенты!$C$6:$C$124,MATCH(15,Контрагенты!$G$6:$G$124,0)),"") | D23: =IFERROR(INDEX(Контрагенты!$D$6:$D$124,MATCH(15,Контрагенты!$G$6:$G$124,0)),"") | E23: =IFERROR(INDEX(Контрагенты!$E$6:$E$124,MATCH(15,Контрагенты!$G$6:$G$124,0)),"")
B24: =IFERROR(INDEX(Контрагенты!$B$6:$B$124,MATCH(16,Контрагенты!$G$6:$G$124,0)),"") | C24: =IFERROR(INDEX(Контрагенты!$C$6:$C$124,MATCH(16,Контрагенты!$G$6:$G$124,0)),"") | D24: =IFERROR(INDEX(Контрагенты!$D$6:$D$124,MATCH(16,Контрагенты!$G$6:$G$124,0)),"") | E24: =IFERROR(INDEX(Контрагенты!$E$6:$E$124,MATCH(16,Контрагенты!$G$6:$G$124,0)),"")
B25: =IFERROR(INDEX(Контрагенты!$B$6:$B$124,MATCH(17,Контрагенты!$G$6:$G$124,0)),"") | C25: =IFERROR(INDEX(Контрагенты!$C$6:$C$124,MATCH(17,Контрагенты!$G$6:$G$124,0)),"") | D25: =IFERROR(INDEX(Контрагенты!$D$6:$D$124,MATCH(17,Контрагенты!$G$6:$G$124,0)),"") | E25: =IFERROR(INDEX(Контрагенты!$E$6:$E$124,MATCH(17,Контрагенты!$G$6:$G$124,0)),"")
B26: =IFERROR(INDEX(Контрагенты!$B$6:$B$124,MATCH(18,Контрагенты!$G$6:$G$124,0)),"") | C26: =IFERROR(INDEX(Контрагенты!$C$6:$C$124,MATCH(18,Контрагенты!$G$6:$G$124,0)),"") | D26: =IFERROR(INDEX(Контрагенты!$D$6:$D$124,MATCH(18,Контрагенты!$G$6:$G$124,0)),"") | E26: =IFERROR(INDEX(Контрагенты!$E$6:$E$124,MATCH(18,Контрагенты!$G$6:$G$124,0)),"")
B27: =IFERROR(INDEX(Контрагенты!$B$6:$B$124,MATCH(19,Контрагенты!$G$6:$G$124,0)),"") | C27: =IFERROR(INDEX(Контрагенты!$C$6:$C$124,MATCH(19,Контрагенты!$G$6:$G$124,0)),"") | D27: =IFERROR(INDEX(Контрагенты!$D$6:$D$124,MATCH(19,Контрагенты!$G$6:$G$124,0)),"") | E27: =IFERROR(INDEX(Контрагенты!$E$6:$E$124,MATCH(19,Контрагенты!$G$6:$G$124,0)),"")
B28: =IFERROR(INDEX(Контрагенты!$B$6:$B$124,MATCH(20,Контрагенты!$G$6:$G$124,0)),"") | C28: =IFERROR(INDEX(Контрагенты!$C$6:$C$124,MATCH(20,Контрагенты!$G$6:$G$124,0)),"") | D28: =IFERROR(INDEX(Контрагенты!$D$6:$D$124,MATCH(20,Контрагенты!$G$6:$G$124,0)),"") | E28: =IFERROR(INDEX(Контрагенты!$E$6:$E$124,MATCH(20,Контрагенты!$G$6:$G$124,0)),"")
B29: =IFERROR(INDEX(Контрагенты!$B$6:$B$124,MATCH(21,Контрагенты!$G$6:$G$124,0)),"") | C29: =IFERROR(INDEX(Контрагенты!$C$6:$C$124,MATCH(21,Контрагенты!$G$6:$G$124,0)),"") | D29: =IFERROR(INDEX(Контрагенты!$D$6:$D$124,MATCH(21,Контрагенты!$G$6:$G$124,0)),"") | E29: =IFERROR(INDEX(Контрагенты!$E$6:$E$124,MATCH(21,Контрагенты!$G$6:$G$124,0)),"")
B30: =IFERROR(INDEX(Контрагенты!$B$6:$B$124,MATCH(22,Контрагенты!$G$6:$G$124,0)),"") | C30: =IFERROR(INDEX(Контрагенты!$C$6:$C$124,MATCH(22,Контрагенты!$G$6:$G$124,0)),"") | D30: =IFERROR(INDEX(Контрагенты!$D$6:$D$124,MATCH(22,Контрагенты!$G$6:$G$124,0)),"") | E30: =IFERROR(INDEX(Контрагенты!$E$6:$E$124,MATCH(22,Контрагенты!$G$6:$G$124,0)),"")
B31: =IFERROR(INDEX(Контрагенты!$B$6:$B$124,MATCH(23,Контрагенты!$G$6:$G$124,0)),"") | C31: =IFERROR(INDEX(Контрагенты!$C$6:$C$124,MATCH(23,Контрагенты!$G$6:$G$124,0)),"") | D31: =IFERROR(INDEX(Контрагенты!$D$6:$D$124,MATCH(23,Контрагенты!$G$6:$G$124,0)),"") | E31: =IFERROR(INDEX(Контрагенты!$E$6:$E$124,MATCH(23,Контрагенты!$G$6:$G$124,0)),"")
B32: =IFERROR(INDEX(Контрагенты!$B$6:$B$124,MATCH(24,Контрагенты!$G$6:$G$124,0)),"") | C32: =IFERROR(INDEX(Контрагенты!$C$6:$C$124,MATCH(24,Контрагенты!$G$6:$G$124,0)),"") | D32: =IFERROR(INDEX(Контрагенты!$D$6:$D$124,MATCH(24,Контрагенты!$G$6:$G$124,0)),"") | E32: =IFERROR(INDEX(Контрагенты!$E$6:$E$124,MATCH(24,Контрагенты!$G$6:$G$124,0)),"")
B33: =IFERROR(INDEX(Контрагенты!$B$6:$B$124,MATCH(25,Контрагенты!$G$6:$G$124,0)),"") | C33: =IFERROR(INDEX(Контрагенты!$C$6:$C$124,MATCH(25,Контрагенты!$G$6:$G$124,0)),"") | D33: =IFERROR(INDEX(Контрагенты!$D$6:$D$124,MATCH(25,Контрагенты!$G$6:$G$124,0)),"") | E33: =IFERROR(INDEX(Контрагенты!$E$6:$E$124,MATCH(25,Контрагенты!$G$6:$G$124,0)),"")
B34: =IFERROR(INDEX(Контрагенты!$B$6:$B$124,MATCH(26,Контрагенты!$G$6:$G$124,0)),"") | C34: =IFERROR(INDEX(Контрагенты!$C$6:$C$124,MATCH(26,Контрагенты!$G$6:$G$124,0)),"") | D34: =IFERROR(INDEX(Контрагенты!$D$6:$D$124,MATCH(26,Контрагенты!$G$6:$G$124,0)),"") | E34: =IFERROR(INDEX(Контрагенты!$E$6:$E$124,MATCH(26,Контрагенты!$G$6:$G$124,0)),"")
B35: =IFERROR(INDEX(Контрагенты!$B$6:$B$124,MATCH(27,Контрагенты!$G$6:$G$124,0)),"") | C35: =IFERROR(INDEX(Контрагенты!$C$6:$C$124,MATCH(27,Контрагенты!$G$6:$G$124,0)),"") | D35: =IFERROR(INDEX(Контрагенты!$D$6:$D$124,MATCH(27,Контрагенты!$G$6:$G$124,0)),"") | E35: =IFERROR(INDEX(Контрагенты!$E$6:$E$124,MATCH(27,Контрагенты!$G$6:$G$124,0)),"")
B36: =IFERROR(INDEX(Контрагенты!$B$6:$B$124,MATCH(28,Контрагенты!$G$6:$G$124,0)),"") | C36: =IFERROR(INDEX(Контрагенты!$C$6:$C$124,MATCH(28,Контрагенты!$G$6:$G$124,0)),"") | D36: =IFERROR(INDEX(Контрагенты!$D$6:$D$124,MATCH(28,Контрагенты!$G$6:$G$124,0)),"") | E36: =IFERROR(INDEX(Контрагенты!$E$6:$E$124,MATCH(28,Контрагенты!$G$6:$G$124,0)),"")
B37: =IFERROR(INDEX(Контрагенты!$B$6:$B$124,MATCH(29,Контрагенты!$G$6:$G$124,0)),"") | C37: =IFERROR(INDEX(Контрагенты!$C$6:$C$124,MATCH(29,Контрагенты!$G$6:$G$124,0)),"") | D37: =IFERROR(INDEX(Контрагенты!$D$6:$D$124,MATCH(29,Контрагенты!$G$6:$G$124,0)),"") | E37: =IFERROR(INDEX(Контрагенты!$E$6:$E$124,MATCH(29,Контрагенты!$G$6:$G$124,0)),"")
B38: =IFERROR(INDEX(Контрагенты!$B$6:$B$124,MATCH(30,Контрагенты!$G$6:$G$124,0)),"") | C38: =IFERROR(INDEX(Контрагенты!$C$6:$C$124,MATCH(30,Контрагенты!$G$6:$G$124,0)),"") | D38: =IFERROR(INDEX(Контрагенты!$D$6:$D$124,MATCH(30,Контрагенты!$G$6:$G$124,0)),"") | E38: =IFERROR(INDEX(Контрагенты!$E$6:$E$124,MATCH(30,Контрагенты!$G$6:$G$124,0)),"")
B39: =IFERROR(INDEX(Контрагенты!$B$6:$B$124,MATCH(31,Контрагенты!$G$6:$G$124,0)),"") | C39: =IFERROR(INDEX(Контрагенты!$C$6:$C$124,MATCH(31,Контрагенты!$G$6:$G$124,0)),"") | D39: =IFERROR(INDEX(Контрагенты!$D$6:$D$124,MATCH(31,Контрагенты!$G$6:$G$124,0)),"") | E39: =IFERROR(INDEX(Контрагенты!$E$6:$E$124,MATCH(31,Контрагенты!$G$6:$G$124,0)),"")
B40: =IFERROR(INDEX(Контрагенты!$B$6:$B$124,MATCH(32,Контрагенты!$G$6:$G$124,0)),"") | C40: =IFERROR(INDEX(Контрагенты!$C$6:$C$124,MATCH(32,Контрагенты!$G$6:$G$124,0)),"") | D40: =IFERROR(INDEX(Контрагенты!$D$6:$D$124,MATCH(32,Контрагенты!$G$6:$G$124,0)),"") | E40: =IFERROR(INDEX(Контрагенты!$E$6:$E$124,MATCH(32,Контрагенты!$G$6:$G$124,0)),"")
B41: =IFERROR(INDEX(Контрагенты!$B$6:$B$124,MATCH(33,Контрагенты!$G$6:$G$124,0)),"") | C41: =IFERROR(INDEX(Контрагенты!$C$6:$C$124,MATCH(33,Контрагенты!$G$6:$G$124,0)),"") | D41: =IFERROR(INDEX(Контрагенты!$D$6:$D$124,MATCH(33,Контрагенты!$G$6:$G$124,0)),"") | E41: =IFERROR(INDEX(Контрагенты!$E$6:$E$124,MATCH(33,Контрагенты!$G$6:$G$124,0)),"")
B42: =IFERROR(INDEX(Контрагенты!$B$6:$B$124,MATCH(34,Контрагенты!$G$6:$G$124,0)),"") | C42: =IFERROR(INDEX(Контрагенты!$C$6:$C$124,MATCH(34,Контрагенты!$G$6:$G$124,0)),"") | D42: =IFERROR(INDEX(Контрагенты!$D$6:$D$124,MATCH(34,Контрагенты!$G$6:$G$124,0)),"") | E42: =IFERROR(INDEX(Контрагенты!$E$6:$E$124,MATCH(34,Контрагенты!$G$6:$G$124,0)),"")
B43: =IFERROR(INDEX(Контрагенты!$B$6:$B$124,MATCH(35,Контрагенты!$G$6:$G$124,0)),"") | C43: =IFERROR(INDEX(Контрагенты!$C$6:$C$124,MATCH(35,Контрагенты!$G$6:$G$124,0)),"") | D43: =IFERROR(INDEX(Контрагенты!$D$6:$D$124,MATCH(35,Контрагенты!$G$6:$G$124,0)),"") | E43: =IFERROR(INDEX(Контрагенты!$E$6:$E$124,MATCH(35,Контрагенты!$G$6:$G$124,0)),"")
...

Sheet Статьи
B2: Статьи расходов
B3: Сумма статьи — SUMIF по листу «Контрагенты». База для доли переключается в C4. | C3: =IF($C$4="суммы по контрагентам",Контрагенты!$C$125,Свод!$C$143)
B4: Доля считается от: | C4: расходов учредителей
B6: Статья | C6: Блок | D6: Сумма | E6: Доля | F6: Контрагентов
B7: МЕДИЦИНСКИЕ
B8: Анализы | C8: медицинские | D8: =SUMIF(Контрагенты!$D$6:$D$124,B8&"",Контрагенты!$C$6:$C$124) | E8: =IF($C$3=0,0,D8/$C$3) | F8: =COUNTIF(Контрагенты!$D$6:$D$124,B8&"")
B9: Аренда Inmode | C9: медицинские | D9: =SUMIF(Контрагенты!$D$6:$D$124,B9&"",Контрагенты!$C$6:$C$124) | E9: =IF($C$3=0,0,D9/$C$3) | F9: =COUNTIF(Контрагенты!$D$6:$D$124,B9&"")
B10: Белье | C10: медицинские | D10: =SUMIF(Контрагенты!$D$6:$D$124,B10&"",Контрагенты!$C$6:$C$124) | E10: =IF($C$3=0,0,D10/$C$3) | F10: =COUNTIF(Контрагенты!$D$6:$D$124,B10&"")
B11: Бланки, мед.журналы, мед.книжки | C11: медицинские | D11: =SUMIF(Контрагенты!$D$6:$D$124,B11&"",Контрагенты!$C$6:$C$124) | E11: =IF($C$3=0,0,D11/$C$3) | F11: =COUNTIF(Контрагенты!$D$6:$D$124,B11&"")
B12: Вывоз ТКО и мед отходов | C12: медицинские | D12: =SUMIF(Контрагенты!$D$6:$D$124,B12&"",Контрагенты!$C$6:$C$124) | E12: =IF($C$3=0,0,D12/$C$3) | F12: =COUNTIF(Контрагенты!$D$6:$D$124,B12&"")
B13: Гонорары ИП хирургов | C13: медицинские | D13: =SUMIF(Контрагенты!$D$6:$D$124,B13&"",Контрагенты!$C$6:$C$124) | E13: =IF($C$3=0,0,D13/$C$3) | F13: =COUNTIF(Контрагенты!$D$6:$D$124,B13&"")
B14: ИП Завиркин А.В. | C14: медицинские | D14: =SUMIF(Контрагенты!$D$6:$D$124,B14&"",Контрагенты!$C$6:$C$124) | E14: =IF($C$3=0,0,D14/$C$3) | F14: =COUNTIF(Контрагенты!$D$6:$D$124,B14&"")
B15: ИП Чугуевская (ЗП Заведягин ОН) | C15: медицинские | D15: =SUMIF(Контрагенты!$D$6:$D$124,B15&"",Контрагенты!$C$6:$C$124) | E15: =IF($C$3=0,0,D15/$C$3) | F15: =COUNTIF(Контрагенты!$D$6:$D$124,B15&"")
B16: Импланты | C16: медицинские | D16: =SUMIF(Контрагенты!$D$6:$D$124,B16&"",Контрагенты!$C$6:$C$124) | E16: =IF($C$3=0,0,D16/$C$3) | F16: =COUNTIF(Контрагенты!$D$6:$D$124,B16&"")
B17: Кровь | C17: медицинские | D17: =SUMIF(Контрагенты!$D$6:$D$124,B17&"",Контрагенты!$C$6:$C$124) | E17: =IF($C$3=0,0,D17/$C$3) | F17: =COUNTIF(Контрагенты!$D$6:$D$124,B17&"")
B18: Лекарства | C18: медицинские | D18: =SUMIF(Контрагенты!$D$6:$D$124,B18&"",Контрагенты!$C$6:$C$124) | E18: =IF($C$3=0,0,D18/$C$3) | F18: =COUNTIF(Контрагенты!$D$6:$D$124,B18&"")
B19: Мед.инструмент | C19: медицинские | D19: =SUMIF(Контрагенты!$D$6:$D$124,B19&"",Контрагенты!$C$6:$C$124) | E19: =IF($C$3=0,0,D19/$C$3) | F19: =COUNTIF(Контрагенты!$D$6:$D$124,B19&"")
... B28: Утилизация медотходов | C28: медицинские | D28: =SUMIF(Контрагенты!$D$6:$D$124,B28&"",Контрагенты!$C$6:$C$124) | E28: =IF($C$3=0,0,D28/$C$3) | F28: =COUNTIF(Контрагенты!$D$6:$D$124,B28&"")
B29: Итого «медицинские» | D29: =SUM(D8:D28) | E29: =IF($C$3=0,0,D29/$C$3)
B31: УПРАВЛЕНЧЕСКИЕ
B32: IT услуги | C32: управленческие | D32: =SUMIF(Контрагенты!$D$6:$D$124,B32&"",Контрагенты!$C$6:$C$124) | E32: =IF($C$3=0,0,D32/$C$3) | F32: =COUNTIF(Контрагенты!$D$6:$D$124,B32&"")
B33: Аренда Самокатная 1 стр1 | C33: управленческие | D33: =SUMIF(Контрагенты!$D$6:$D$124,B33&"",Контрагенты!$C$6:$C$124) | E33: =IF($C$3=0,0,D33/$C$3) | F33: =COUNTIF(Контрагенты!$D$6:$D$124,B33&"")
B34: Аренда кофемашины | C34: управленческие | D34: =SUMIF(Контрагенты!$D$6:$D$124,B34&"",Контрагенты!$C$6:$C$124) | E34: =IF($C$3=0,0,D34/$C$3) | F34: =COUNTIF(Контрагенты!$D$6:$D$124,B34&"")
B35: Битрикс 24 | C35: управленческие | D35: =SUMIF(Контрагенты!$D$6:$D$124,B35&"",Контрагенты!$C$6:$C$124) | E35: =IF($C$3=0,0,D35/$C$3) | F35: =COUNTIF(Контрагенты!$D$6:$D$124,B35&"")
B36: Внедрение финансового учёта | C36: управленческие | D36: =SUMIF(Контрагенты!$D$6:$D$124,B36&"",Контрагенты!$C$6:$C$124) | E36: =IF($C$3=0,0,D36/$C$3) | F36: =COUNTIF(Контрагенты!$D$6:$D$124,B36&"")
B37: Вода | C37: управленческие | D37: =SUMIF(Контрагенты!$D$6:$D$124,B37&"",Контрагенты!$C$6:$C$124) | E37: =IF($C$3=0,0,D37/$C$3) | F37: =COUNTIF(Контрагенты!$D$6:$D$124,B37&"")
B38: Дизайн-услуги | C38: управленческие | D38: =SUMIF(Контрагенты!$D$6:$D$124,B38&"",Контрагенты!$C$6:$C$124) | E38: =IF($C$3=0,0,D38/$C$3) | F38: =COUNTIF(Контрагенты!$D$6:$D$124,B38&"")
B39: Доставка | C39: управленческие | D39: =SUMIF(Контрагенты!$D$6:$D$124,B39&"",Контрагенты!$C$6:$C$124) | E39: =IF($C$3=0,0,D39/$C$3) | F39: =COUNTIF(Контрагенты!$D$6:$D$124,B39&"")
B40: Интернет | C40: управленческие | D40: =SUMIF(Контрагенты!$D$6:$D$124,B40&"",Контрагенты!$C$6:$C$124) | E40: =IF($C$3=0,0,D40/$C$3) | F40: =COUNTIF(Контрагенты!$D$6:$D$124,B40&"")
B41: Канц и хоз расходы | C41: управленческие | D41: =SUMIF(Контрагенты!$D$6:$D$124,B41&"",Контрагенты!$C$6:$C$124) | E41: =IF($C$3=0,0,D41/$C$3) | F41: =COUNTIF(Контрагенты!$D$6:$D$124,B41&"")
B42: Консультационные услуги | C42: управленческие | D42: =SUMIF(Контрагенты!$D$6:$D$124,B42&"",Контрагенты!$C$6:$C$124) | E42: =IF($C$3=0,0,D42/$C$3) | F42: =COUNTIF(Контрагенты!$D$6:$D$124,B42&"")
B43: Косметология | C43: управленческие | D43: =SUMIF(Контрагенты!$D$6:$D$124,B43&"",Контрагенты!$C$6:$C$124) | E43: =IF($C$3=0,0,D43/$C$3) | F43: =COUNTIF(Контрагенты!$D$6:$D$124,B43&"")
... B81: Электрооборудование | C81: управленческие | D81: =SUMIF(Контрагенты!$D$6:$D$124,B81&"",Контрагенты!$C$6:$C$124) | E81: =IF($C$3=0,0,D81/$C$3) | F81: =COUNTIF(Контрагенты!$D$6:$D$124,B81&"")
B82: Итого «управленческие» | D82: =SUM(D32:D81) | E82: =IF($C$3=0,0,D82/$C$3)
B84: ВСЕГО ПО СТАТЬЯМ | D84: =D29+D82 | F84: должно совпасть с суммой по контрагентам
